<?xml version="1.0"?>

<robot name="vision_robot">

  <!-- World Link -->
  <!-- <link name="world"/> -->

  <!-- Base Link -->
  <link name="base_link">

    <visual>
      <geometry>
        <box size="0.4 0.3 0.1"/>
      </geometry>
      <origin xyz="0 0 0.05"/>
    </visual>

    <collision>
      <geometry>
        <box size="0.4 0.3 0.1"/>
      </geometry>
      <origin xyz="0 0 0.05"/>
    </collision>

    <inertial>
      <mass value="5.0"/>
      <origin xyz="0 0 0.05"/>
      <inertia
        ixx="0.1" ixy="0.0" ixz="0.0"
        iyy="0.1" iyz="0.0"
        izz="0.1"/>
    </inertial>

  </link>

  <!-- Fixed Joint Connecting Robot to World -->
  <!-- <joint name="world_to_base" type="fixed">
    <parent link="world"/>
    <child link="base_link"/>
    <origin xyz="0 0 0"/>
  </joint> -->

<link name="left_wheel">

  <visual>
    <geometry>
      <cylinder radius="0.05" length="0.02"/>
    </geometry>
    <origin xyz="0 0 0" rpy="1.57 0 0"/>
  </visual>

  <collision>
    <geometry>
      <cylinder radius="0.05" length="0.02"/>
    </geometry>
    <origin xyz="0 0 0" rpy="1.57 0 0"/>
  </collision>

  <inertial>
    <mass value="0.5"/>
    <inertia
      ixx="0.001" ixy="0" ixz="0"
      iyy="0.001" iyz="0"
      izz="0.001"/>
  </inertial>

</link>

<gazebo reference="left_wheel">
  <mu1>1.0</mu1>
  <mu2>1.0</mu2>
</gazebo>

<joint name="left_wheel_joint" type="continuous">

  <parent link="base_link"/>
  <child link="left_wheel"/>

  <origin xyz="0 0.15 0.05"/>

  <axis xyz="0 1 0"/>

</joint>

<link name="right_wheel">

  <visual>
    <geometry>
      <cylinder radius="0.05" length="0.02"/>
    </geometry>
    <origin xyz="0 0 0" rpy="1.57 0 0"/>
  </visual>

  <collision>
    <geometry>
      <cylinder radius="0.05" length="0.02"/>
    </geometry>
    <origin xyz="0 0 0" rpy="1.57 0 0"/>
  </collision>

  <inertial>
    <mass value="0.5"/>
    <inertia
      ixx="0.001" ixy="0" ixz="0"
      iyy="0.001" iyz="0"
      izz="0.001"/>
  </inertial>

</link>

<gazebo reference="right_wheel">
  <mu1>1.0</mu1>
  <mu2>1.0</mu2>
</gazebo>

<joint name="right_wheel_joint" type="continuous">

  <parent link="base_link"/>
  <child link="right_wheel"/>

  <origin xyz="0 -0.15 0.05"/>

  <axis xyz="0 1 0"/>

</joint>

<link name="caster_wheel">

  <visual>
    <geometry>
      <sphere radius="0.03"/>
    </geometry>
  </visual>

</link>

<joint name="caster_joint" type="fixed">

  <parent link="base_link"/>
  <child link="caster_wheel"/>

  <origin xyz="-0.15 0 0.03"/>

</joint>

<link name="lidar_link">

  <visual>
    <geometry>
      <cylinder radius="0.04" length="0.05"/>
    </geometry>
    <origin xyz="0 0 0"/>
    <material name="black">
      <color rgba="0.1 0.1 0.1 1"/>
    </material>
  </visual>

</link>

<joint name="lidar_joint" type="fixed">

  <parent link="base_link"/>
  <child link="lidar_link"/>

  <origin xyz="0 0 0.12"/>

</joint>

<gazebo reference="lidar_link">

  <sensor type="ray" name="lidar_sensor">

    <pose>0 0 0 0 0 0</pose>

    <visualize>true</visualize>

    <update_rate>10</update_rate>

    <ray>

      <scan>
        <horizontal>
          <samples>360</samples>
          <resolution>1</resolution>
          <min_angle>-3.14</min_angle>
          <max_angle>3.14</max_angle>
        </horizontal>
      </scan>

      <range>
        <min>0.12</min>
        <max>8.0</max>
        <resolution>0.01</resolution>
      </range>

    </ray>

    <!-- <plugin name="gazebo_ros_laser" filename="libgazebo_ros_ray_sensor.so">
  <ros>
    <remapping>~/out:=/scan</remapping>
  </ros>
  <frameName>lidar_link</frameName>
</plugin> -->

<plugin name="gazebo_ros_laser" filename="libgazebo_ros_ray_sensor.so">

  <ros>
    <namespace>/</namespace>
    <remapping>~/out:=/scan</remapping>
  </ros>

  <output_type>sensor_msgs/LaserScan</output_type>

  <frame_name>lidar_link</frame_name>

</plugin>

  </sensor>

</gazebo>

<!-- <gazebo>
  <plugin name="diff_drive_controller" filename="libgazebo_ros_diff_drive.so">

    <ros>
      <namespace>/</namespace>
    </ros>

    <left_joint>left_wheel_joint</left_joint>
    <right_joint>right_wheel_joint</right_joint>

    <wheel_separation>0.30</wheel_separation>
    <wheel_diameter>0.10</wheel_diameter>

    <command_topic>cmd_vel</command_topic>

    <odometry_topic>odom</odometry_topic>
    <odometry_frame>odom</odometry_frame>
    <robot_base_frame>base_link</robot_base_frame>

    <publish_odom>true</publish_odom>
    <publish_odom_tf>true</publish_odom_tf>

  </plugin>
</gazebo> -->

<gazebo>
  <plugin name="gazebo_ros_diff_drive" filename="libgazebo_ros_diff_drive.so">

    <left_joint>left_wheel_joint</left_joint>
    <right_joint>right_wheel_joint</right_joint>

    <wheel_separation>0.30</wheel_separation>
    <wheel_diameter>0.10</wheel_diameter>

    <command_topic>cmd_vel</command_topic>

    <odometry_topic>odom</odometry_topic>
    <odometry_frame>odom</odometry_frame>

    <robot_base_frame>base_link</robot_base_frame>

    <publish_odom>true</publish_odom>
    <publish_odom_tf>true</publish_odom_tf>

    <update_rate>50</update_rate>

  </plugin>
</gazebo>

</robot>
